<?xml version="1.0" ?>
<!-- =================================================================================== -->
<!-- |    This document was autogenerated by xacro from open_manipulator.urdf.xacro    | -->
<!-- |    EDITING THIS FILE BY HAND IS NOT RECOMMENDED                                 | -->
<!-- =================================================================================== -->
<!-- Open_Manipulator Chain -->
<robot name="open_manipulator">
  <!-- World -->
  <gazebo reference="world">
  </gazebo>
  <!-- Link1 -->
  <RefLink ref="link1"/>
  <!-- Link2 -->
  <RefLink ref="link2"/>
  <!-- Link3 -->
  <RefLink ref="link3"/>
  <!-- Link4 -->
  <RefLink ref="link4"/>
  <!-- Link5 -->
  <RefLink ref="link5"/>
  <!-- Link6 -->
  <RefLink ref="link6"/>
  <!-- Link7 -->
  <RefLink ref="link7"/>
  <!-- gripper_link -->
  <RefLink ref="gripper_link"/>
  <!-- gripper_link_sub -->
  <RefLink ref="gripper_link_sub"/>
  <!-- end effector link -->
  <gazebo reference="end_effector_link">
    <material>Gazebo/Red</material>
  </gazebo>
  <!-- ros_control plugin -->
  <gazebo>
    <plugin filename="libgazebo_ros_control.so" name="gazebo_ros_control">
      <!-- <robotNamespace>mikata_arm</robotNamespace> -->
      <controlPeriod>0.001</controlPeriod>
      <robotSimType>gazebo_ros_control/DefaultRobotHWSim</robotSimType>
      <legacyModeNS>true</legacyModeNS>
    </plugin>
  </gazebo>
  <material name="black">
    <color rgba="0.0 0.0 0.0 1.0"/>
  </material>
  <material name="white">
    <color rgba="1.0 1.0 1.0 1.0"/>
  </material>
  <material name="red">
    <color rgba="0.8 0.0 0.0 1.0"/>
  </material>
  <material name="blue">
    <color rgba="0.0 0.0 0.8 1.0"/>
  </material>
  <material name="green">
    <color rgba="0.0 0.8 0.0 1.0"/>
  </material>
  <material name="grey">
    <color rgba="0.5 0.5 0.5 1.0"/>
  </material>
  <material name="orange">
    <color rgba="1.0 0.4235294117647059 0.0392156862745098 1.0"/>
  </material>
  <material name="brown">
    <color rgba="0.8705882352941177 0.8117647058823529 0.7647058823529411 1.0"/>
  </material>
  <!-- World -->
  <link name="world">
  </link>
  <!-- World fixed joint-->
  <joint name="world_fixed" type="fixed">
    <origin rpy="0 0 0" xyz="0 0 0"/>
    <parent link="world"/>
    <child link="link1"/>
  </joint>
  <link name="camera_frame" />
   <link name="camera_optical_frame" />
  <joint name="camera_setting" type="fixed" >
	　<parent link="world" />
	　<child  link="camera_frame" />
	<origin xyz="0.503 0.0224 0.642" rpy="3.14 0 0" />
  </joint>
  <!-- Link 1 -->
  <link name="link1">
    <visual>
      <origin rpy="-1.5707963267948966 0 0" xyz="0 0 0.027"/>
      <geometry>
        <mesh filename="package://open_manipulator_description/meshes/chain_link1.stl"/>
      </geometry>
      <material name="grey"/>
    </visual>
    <collision>
      <origin rpy="-1.5707963267948966 0 0" xyz="0 0 0.027"/>
      <geometry>
        <mesh filename="package://open_manipulator_description/meshes/chain_link1.stl"/>
      </geometry>
    </collision>
    <!-- <inertial> -->
    <!--   <origin xyz="-0.016911 -7.3022E-05 -0.0080745" rpy="${-pi/2} 0 0" /> -->
    <!--   <mass value="0.14147" /> -->
    <!--   <inertia ixx="2.1813E-05" ixy="-1.7015E-08" ixz="-8.9152E-07" -->
    <!--            iyy="2.3447E-05" iyz="-1.5454E-07" -->
    <!--            izz="1.6364E-06" /> -->
    <!-- </inertial> -->
    <inertial>
      <origin xyz="3.0876154e-04 0.0000000e+00 -1.2176461e-04"/>
      <mass value="7.9119962e-02"/>
      <inertia ixx="1.2505234e-05" ixy="0.0" ixz="-1.7855208e-07" iyy="2.1898364e-05" iyz="0.0" izz="1.9267361e-05"/>
    </inertial>
  </link>
  <!-- Joint 1 -->
  <joint name="joint1" type="revolute">
    <parent link="link1"/>
    <child link="link2"/>
    <origin rpy="0 0 0" xyz="0 0 0.0515"/>
    <axis xyz="0 0 1"/>
    <limit effort="1" lower="-2.8776988706882505" upper="2.8776988706882505" velocity="4.8"/>
  </joint>
  <transmission name="tran1">
    <type>transmission_interface/SimpleTransmission</type>
    <joint name="joint1">
      <hardwareInterface>hardware_interface/PositionJointInterface</hardwareInterface>
    </joint>
    <actuator name="motor1">
      <hardwareInterface>hardware_interface/PositionJointInterface</hardwareInterface>
      <mechanicalReduction>1</mechanicalReduction>
    </actuator>
  </transmission>
  <!--  Link 2 -->
  <link name="link2">
    <visual>
      <origin rpy="0 0 -1.5707963267948966" xyz="0 0 0"/>
      <geometry>
        <mesh filename="package://open_manipulator_description/meshes/chain_link2.stl"/>
      </geometry>
      <material name="grey"/>
    </visual>
    <collision>
      <origin rpy="0 0 1.5707963267948966" xyz="0 0 0"/>
      <geometry>
        <mesh filename="package://open_manipulator_description/meshes/chain_link2.stl"/>
      </geometry>
    </collision>
    <!-- <inertial> -->
    <!--   <origin xyz="-0.00042334871953208 0.0005762171718733 0.0387383572136045" rpy="0 0 0" /> -->
    <!--   <mass value="0.129397139554481" /> -->
    <!--   <inertia ixx="3.69350041678783E-05" ixy="-3.89313759320941E-08" ixz="-1.11653037527299E-08" -->
    <!--            iyy="3.68198693987775E-05" iyz="-1.1111795426955E-06" -->
    <!--            izz="1.48030530212799E-07" /> -->
    <!-- </inertial> -->
    <inertial>
      <origin xyz="-3.0184870e-04 5.4043684e-04 0.047433463999999995"/>
      <mass value="9.8406837e-02"/>
      <inertia ixx="3.4543422e-05" ixy="-1.6031095e-08" ixz="-3.8375155e-07" iyy="3.2689329e-05" iyz="2.8511935e-08" izz="1.8850320e-05"/>
    </inertial>
  </link>
  <!--  Joint 2 -->
  <joint name="joint2" type="revolute">
    <parent link="link2"/>
    <child link="link3"/>
    <origin rpy="0 0 0" xyz="0 0 0.05475"/>
    <axis xyz="0 1 0"/>
    <limit effort="1" lower="-2.098269733332623" upper="1.8739600178663116" velocity="4.8"/>
  </joint>
  <transmission name="tran2">
    <type>transmission_interface/SimpleTransmission</type>
    <joint name="joint2">
      <hardwareInterface>hardware_interface/PositionJointInterface</hardwareInterface>
    </joint>
    <actuator name="motor2">
      <hardwareInterface>hardware_interface/PositionJointInterface</hardwareInterface>
      <mechanicalReduction>1</mechanicalReduction>
    </actuator>
  </transmission>
  <!--  Link 3 -->
  <link name="link3">
    <visual>
      <origin rpy="1.5707963267948966 0 0" xyz="0 -0.026 0"/>
      <geometry>
        <mesh filename="package://open_manipulator_description/meshes/chain_link3.stl"/>
      </geometry>
      <material name="grey"/>
    </visual>
    <collision>
      <origin rpy="1.5707963267948966 0 0" xyz="0 -0.026 0"/>
      <geometry>
        <mesh filename="package://open_manipulator_description/meshes/chain_link3.stl"/>
      </geometry>
    </collision>
    <!-- <inertial> -->
    <!--   <origin xyz="0.00634911017847554 0.105401689990389 -0.0262056408085307" rpy="0 0 0" /> -->
    <!--   <mass value="0.12120137926006" /> -->
    <!--   <inertia ixx="0.000489960675623491" ixy="-5.26672832890087E-05" ixz="1.49822052691775E-07" -->
    <!--            iyy="2.42965312448389E-05" iyz="1.56967790646472E-06" -->
    <!--            izz="0.000482873776104937" /> -->
    <!-- </inertial> -->
    <inertial>
      <origin xyz="1.0308393e-02 3.7743363e-04 1.0170197e-01"/>
      <mass value="1.3850917e-01"/>
      <inertia ixx="3.3055381e-04" ixy="-9.7940978e-08" ixz="-3.8505711e-05" iyy="3.4290447e-04" iyz="-1.5717516e-06" izz="6.0346498e-05"/>
    </inertial>
  </link>
  <!--  Joint 3 -->
  <joint name="joint3" type="revolute">
    <parent link="link3"/>
    <child link="link4"/>
    <origin rpy="0 0 0" xyz="0.024 0 0.1684"/>
    <axis xyz="0 1 0"/>
    <limit effort="1" lower="-1.8017033868337464" upper="1.4074335088082273" velocity="4.8"/>
  </joint>
  <transmission name="tran3">
    <type>transmission_interface/SimpleTransmission</type>
    <joint name="joint3">
      <hardwareInterface>hardware_interface/PositionJointInterface</hardwareInterface>
    </joint>
    <actuator name="motor3">
      <hardwareInterface>hardware_interface/PositionJointInterface</hardwareInterface>
      <mechanicalReduction>1</mechanicalReduction>
    </actuator>
  </transmission>
  <!--  Link 4 -->
  <link name="link4">
    <visual>
      <origin rpy="1.5707963267948966 -1.5707963267948966 0" xyz="0 0.019 0"/>
      <geometry>
        <mesh filename="package://open_manipulator_description/meshes/chain_link4.stl"/>
      </geometry>
      <material name="grey"/>
    </visual>
    <collision>
      <origin rpy="1.5707963267948966 -1.5707963267948966 0" xyz="0 0.019 0"/>
      <geometry>
        <mesh filename="package://open_manipulator_description/meshes/chain_link4.stl"/>
      </geometry>
    </collision>
    <!-- <inertial> -->
    <!--   <origin xyz="0.0107684769865891 -0.0395998807006063 0.0190000000054333" rpy="0 0 0" /> -->
    <!--   <mass value="0.0597850138451838" /> -->
    <!--   <inertia ixx="1.5907540511103E-05" ixy="2.8291751472122E-06" ixz="-6.22476258071719E-13" -->
    <!--            iyy="6.16523427095478E-06" iyz="-7.18764926930745E-15" -->
    <!--            izz="1.15699642937667E-05" /> -->
    <!-- </inertial> -->
    <inertial>
      <origin xyz="9.0909590e-02 3.8929816e-04 2.2413279e-04"/>
      <mass value="1.3274562e-01"/>
      <inertia ixx="3.0654178e-05" ixy="-1.2764155e-06" ixz="-2.6874417e-07" iyy="2.4230292e-04" iyz="1.1559550e-08" izz="2.5155057e-04"/>
    </inertial>
  </link>
  <!--  Joint 4 -->
  <joint name="joint4" type="revolute">
    <parent link="link4"/>
    <child link="link5"/>
    <origin rpy="0 0 0" xyz="0.062 0 0"/>
    <axis xyz="1 0 0"/>
    <limit effort="1" lower="-3.122743097668254" upper="3.122743097668254" velocity="4.8"/>
  </joint>
  <transmission name="tran4">
    <type>transmission_interface/SimpleTransmission</type>
    <joint name="joint4">
      <hardwareInterface>hardware_interface/PositionJointInterface</hardwareInterface>
    </joint>
    <actuator name="motor4">
      <hardwareInterface>hardware_interface/PositionJointInterface</hardwareInterface>
      <mechanicalReduction>1</mechanicalReduction>
    </actuator>
  </transmission>
  <!--  Link 5 -->
  <link name="link5">
    <visual>
      <origin rpy="1.5707963267948966 3.141592653589793 1.5707963267948966" xyz="0 0 0"/>
      <geometry>
        <mesh filename="package://open_manipulator_description/meshes/chain_link5.stl"/>
      </geometry>
      <material name="grey"/>
    </visual>
    <collision>
      <origin rpy="1.5707963267948966 3.141592653589793 1.5707963267948966" xyz="0 0 0"/>
      <geometry>
        <mesh filename="package://open_manipulator_description/meshes/chain_link5.stl"/>
      </geometry>
    </collision>
    <!-- <inertial> -->
    <!--   <origin xyz="-0.000218076760146619 -0.000626191256536957 0.0596980339879584" rpy="0 0 0" /> -->
    <!--   <mass value="0.0796444353162854" /> -->
    <!--   <inertia ixx="6.5346536618451E-05" ixy="1.08804671081198E-08" ixz="3.20425969376465E-07" -->
    <!--            iyy="6.52473697844542E-05" iyz="1.49110423887788E-06" -->
    <!--            izz="3.4317718754864E-07" /> -->
    <!-- </inertial> -->
    <inertial>
      <origin xyz="4.4206755e-02 3.6839985e-07 8.9142216e-03"/>
      <mass value="1.4327573e-01"/>
      <inertia ixx="8.0870749e-05" ixy="0.0" ixz="-1.0157896e-06" iyy="7.5980465e-05" iyz="0.0" izz="9.3127351e-05"/>
    </inertial>
  </link>
  <!--  Joint 5 -->
  <joint name="joint5" type="revolute">
    <parent link="link5"/>
    <child link="link6"/>
    <origin rpy="0 0 0" xyz="0.088 0 0"/>
    <axis xyz="0 1 0"/>
    <limit effort="1" lower="-1.8017033868337464" upper="2.222048483884061" velocity="4.8"/>
  </joint>
  <transmission name="tran5">
    <type>transmission_interface/SimpleTransmission</type>
    <joint name="joint5">
      <hardwareInterface>hardware_interface/PositionJointInterface</hardwareInterface>
    </joint>
    <actuator name="motor5">
      <hardwareInterface>hardware_interface/PositionJointInterface</hardwareInterface>
      <mechanicalReduction>1</mechanicalReduction>
    </actuator>
  </transmission>
  <!--  Link 6 -->
  <link name="link6">
    <visual>
      <origin rpy="1.5707963267948966 1.5707963267948966 0" xyz="0 -0.019 0"/>
      <geometry>
        <mesh filename="package://open_manipulator_description/meshes/chain_link6.stl"/>
      </geometry>
      <material name="grey"/>
    </visual>
    <collision>
      <origin rpy="1.5707963267948966 1.5707963267948966 0" xyz="0 -0.019 0"/>
      <geometry>
        <mesh filename="package://open_manipulator_description/meshes/chain_link6.stl"/>
      </geometry>
    </collision>
    <!-- <inertial> -->
    <!--   <origin xyz="-0.0107684769865891 0.0395998807006062 -0.0189999999945667" rpy="0 0 0" /> -->
    <!--   <mass value="0.0597850138451838" /> -->
    <!--   <inertia ixx="1.59075405111031E-05" ixy="2.8291751472122E-06" ixz="6.22476246848532E-13" -->
    <!--            iyy="6.16523427095479E-06" iyz="7.18764844874428E-15" -->
    <!--            izz="1.15699642937667E-05" /> -->
    <!-- </inertial> -->
    <inertial>
      <origin xyz="4.4206755e-02 3.6839985e-07 8.9142216e-03"/>
      <mass value="1.4327573e-01"/>
      <inertia ixx="8.0870749e-05" ixy="0.0" ixz="-1.0157896e-06" iyy="7.5980465e-05" iyz="0.0" izz="9.3127351e-05"/>
    </inertial>
  </link>
  <!--  Joint 6 -->
  <joint name="joint6" type="revolute">
    <parent link="link6"/>
    <child link="link7"/>
    <origin rpy="0 0 0" xyz="0.062 0 0"/>
    <axis xyz="1 0 0"/>
    <limit effort="1" lower="-3.122743097668254" upper="3.122743097668254" velocity="4.8"/>
  </joint>
  <transmission name="tran6">
    <type>transmission_interface/SimpleTransmission</type>
    <joint name="joint6">
      <hardwareInterface>hardware_interface/PositionJointInterface</hardwareInterface>
    </joint>
    <actuator name="motor6">
      <hardwareInterface>hardware_interface/PositionJointInterface</hardwareInterface>
      <mechanicalReduction>1</mechanicalReduction>
    </actuator>
  </transmission>
  <!--  Link 7 -->
  <link name="link7">
    <visual>
      <origin rpy="0 -1.5707963267948966 0" xyz="0 0 0"/>
      <geometry>
        <mesh filename="package://open_manipulator_description/meshes/chain_link7.stl"/>
      </geometry>
      <material name="grey"/>
    </visual>
    <collision>
      <origin rpy="0 -1.5707963267948966 0" xyz="0 0 0"/>
      <geometry>
        <mesh filename="package://open_manipulator_description/meshes/chain_link7.stl"/>
      </geometry>
    </collision>
    <!-- <inertial> -->
    <!--   <origin xyz="8.11464269925566E-05 -0.00070824109768956 -0.0220980053972996" rpy="0 0 0" /> -->
    <!--   <mass value="0.0741805648173052" /> -->
    <!--   <inertia ixx="5.00300817099651E-06" ixy="-2.1246207546751E-07" ixz="2.45442201688391E-08" -->
    <!--            iyy="9.69324841658574E-06" iyz="-2.18474747851751E-06" -->
    <!--            izz="8.88278852334281E-06" /> -->
    <!-- </inertial> -->
    <inertial>
      <origin xyz="4.4206755e-02 3.6839985e-07 8.9142216e-03"/>
      <mass value="1.4327573e-01"/>
      <inertia ixx="8.0870749e-05" ixy="0.0" ixz="-1.0157896e-06" iyy="7.5980465e-05" iyz="0.0" izz="9.3127351e-05"/>
    </inertial>
  </link>
  <!--  Gripper link -->
  <link name="gripper_link">
    <visual>
      <origin rpy="0 0 0" xyz="0 0 0"/>
      <geometry>
        <mesh filename="package://open_manipulator_description/meshes/chain_link_grip_l.stl"/>
      </geometry>
      <material name="grey"/>
    </visual>
    <collision>
      <origin rpy="0 0 0" xyz="0 0 0"/>
      <geometry>
        <mesh filename="package://open_manipulator_description/meshes/chain_link_grip_l.stl"/>
      </geometry>
    </collision>
    <inertial>
      <origin rpy="0 0 0" xyz="-0.00340216508542759 -0.00576540023107835 -2.1799589910998E-09"/>
      <mass value="0.0356307403873285"/>
      <inertia ixx="1.81811062489467E-05" ixy="2.51217685396069E-06" ixz="-1.0866660092931E-08" iyy="9.13797195647898E-06" iyz="-1.08688133683192E-08" izz="1.03452048539682E-05"/>
    </inertial>
  </link>
  <!--  Gripper joint -->
  <joint name="gripper" type="revolute">
    <parent link="link7"/>
    <child link="gripper_link"/>
    <origin rpy="0 0 0" xyz="0.026 0.016 0"/>
    <axis xyz="0 0 1"/>
    <limit effort="1" lower="-0.7133010663668231" upper="1.059980724428978" velocity="4.8"/>
  </joint>
  <transmission name="tran7">
    <type>transmission_interface/SimpleTransmission</type>
    <joint name="gripper">
      <hardwareInterface>hardware_interface/PositionJointInterface</hardwareInterface>
    </joint>
    <actuator name="motor7">
      <hardwareInterface>hardware_interface/PositionJointInterface</hardwareInterface>
      <mechanicalReduction>1</mechanicalReduction>
    </actuator>
  </transmission>
  <!--  Gripper link sub-->
  <link name="gripper_link_sub">
    <visual>
      <origin rpy="0 0 0" xyz="0 0 0"/>
      <geometry>
        <mesh filename="package://open_manipulator_description/meshes/chain_link_grip_r.stl"/>
      </geometry>
      <material name="grey"/>
    </visual>
    <collision>
      <origin rpy="0 0 0" xyz="0 0 0"/>
      <geometry>
        <mesh filename="package://open_manipulator_description/meshes/chain_link_grip_r.stl"/>
      </geometry>
    </collision>
    <inertial>
      <origin rpy="0 0 0" xyz="0.0347516179427996 0.010629552145661 -0.0270934437190569"/>
      <mass value="0.0460906192162207"/>
      <inertia ixx="1.34126147791776E-05" ixy="-8.10308483393553E-06" ixz="-1.05608290826753E-07" iyy="2.13311499424932E-05" iyz="-6.10789237260564E-08" izz="1.80372747734964E-05"/>
    </inertial>
  </link>
  <!--  Gripper joint sub -->
  <joint name="gripper_sub" type="revolute">
    <parent link="link7"/>
    <child link="gripper_link_sub"/>
    <origin rpy="0 0 0" xyz="0.026 -0.016 0"/>
    <axis xyz="0 0 1"/>
    <limit effort="1" lower="-0.7133010663668231" upper="1.059980724428978" velocity="4.8"/>
    <mimic joint="gripper" multiplier="-1"/>
  </joint>
  <transmission name="tran8">
    <type>transmission_interface/SimpleTransmission</type>
    <joint name="gripper_sub">
      <hardwareInterface>hardware_interface/PositionJointInterface</hardwareInterface>
    </joint>
    <actuator name="motor8">
      <hardwareInterface>hardware_interface/PositionJointInterface</hardwareInterface>
      <mechanicalReduction>1</mechanicalReduction>
    </actuator>
  </transmission>
  <!-- end effector joint -->
  <joint name="end_effector_joint" type="fixed">
    <origin rpy="0 0 0" xyz="0.08375 0 0"/>
    <parent link="link7"/>
    <child link="end_effector_link"/>
  </joint>
  <!-- end effector link -->
  <link name="end_effector_link">
    <visual>
      <origin rpy="0 0 0" xyz="0 0 0"/>
      <geometry>
        <box size="0.01 0.01 0.01"/>
      </geometry>
      <material name="red"/>
    </visual>
    <inertial>
      <origin rpy="0 0 0" xyz="0 0 0"/>
      <mass value="0.001"/>
      <inertia ixx="1.0e-06" ixy="0.0" ixz="0.0" iyy="1.0e-06" iyz="0.0" izz="1.0e-06"/>
    </inertial>
  </link>
</robot>

